import { describe, it, expect, vi, beforeEach, afterEach } from 'vitest';
import { render, screen } from '@testing-library/react';
import { ErrorBoundary } from '../ErrorBoundary';
import { Button } from '@/components/ui/button';

describe('ErrorBoundary', () => {
  const consoleError = console.error;
  beforeEach(() => {
    console.error = vi.fn();
  });

  afterEach(() => {
    console.error = consoleError;
  });

  it('renders children when there is no error', () => {
    render(
      <ErrorBoundary>
        <div>Test Content</div>
      </ErrorBoundary>
    );

    expect(screen.getByText('Test Content')).toBeInTheDocument();
  });

  it('renders error message when there is an error', () => {
    const ThrowError = () => {
      throw new Error('Test error');
    };

    render(
      <ErrorBoundary>
        <ThrowError />
      </ErrorBoundary>
    );

    expect(screen.getByText('Test error')).toBeInTheDocument();
    expect(screen.getByText('Something went wrong!')).toBeInTheDocument();
    expect(screen.getByRole('button', { name: /try again/i })).toBeInTheDocument();
  });

  it('renders custom fallback when provided', () => {
    const ThrowError = () => {
      throw new Error('Test error');
    };

    render(
      <ErrorBoundary fallback={<div>Custom Error View</div>}>
        <ThrowError />
      </ErrorBoundary>
    );

    expect(screen.getByText('Custom Error View')).toBeInTheDocument();
  });

  it('logs error to console', () => {
    const error = new Error('Test error');
    const ThrowError = () => {
      throw error;
    };

    render(
      <ErrorBoundary>
        <ThrowError />
      </ErrorBoundary>
    );

    expect(console.error).toHaveBeenCalledWith(
      'ErrorBoundary caught an error:',
      error,
      expect.any(Object)
    );
  });
});